Workbook

Sheet PMPM
A1: PMPM COST CHANGE ANALYSIS | N1: YEAR | O1: BENES_FFS_CNT | Q1: HCPCS_Cd | R1: Brnd_Name | S1: Gnrc_Name | T1: Tot_Spndng_2018 | U1: Tot_Benes_2018 | V1: Avg_Spndng_Per_Bene_2018 | W1: Tot_Spndng_2021 | X1: Tot_Benes_2021 | Y1: Avg_Spndng_Per_Bene_2021
B2: 2018 | C2: 2021 | N2: 2018 | O2: 33503234 | Q2: J9271 | R2: Keytruda | S2: Pembrolizumab | T2: 1813727267 | U2: 35491 | V2: 51103.865 | W2: 3966530837 | X2: 62830 | Y2: 63131.161
A3: Total Spend | B3: =SUM(T:T) -> 3.1198753e+10 | C3: =SUM(W:W) -> 4.0140961e+10 | N3: 2021 | O3: 30900379 | Q3: J0178 | R3: Eylea | S3: Aflibercept | T3: 2573938387 | U3: 240910 | V3: 10684.232 | W3: 3415890772 | X3: 309699 | Y3: 11029.712
A4: FFS Benes | B4: 33503234 | C4: 30900379 | Q4: J0897 | R4: Prolia* | S4: Denosumab* | T4: 1416968973 | U4: 533286 | V4: 2657.0526 | W4: 1780811015 | X4: 629724 | Y4: 2827.923
A5: PMPM | B5: =B3/(B4*12) -> 77.601348 | C5: =C3/(C4*12) -> 108.25369 | Q5: J9299 | R5: Opdivo | S5: Nivolumab | T5: 1715907188 | U5: 32846 | V5: 52240.979 | W5: 1573611853 | X5: 25426 | Y5: 61889.871
Q6: J9144 | R6: Darzalex Faspro | S6: Daratumumab-Hyaluronidase-Fihj | W6: 1046702030 | X6: 12490 | Y6: 83803.205
A7: Total Change | B7: =C5-B5 -> 30.652342 | Q7: J2778 | R7: Lucentis | S7: Ranibizumab | T7: 1215701656 | U7: 123389 | V7: 9852.5935 | W7: 1044929993 | X7: 114432 | Y7: 9131.4492
Q8: J0129 | R8: Orencia* | S8: Abatacept* | T8: 7.9928609e+08 | U8: 26726 | V8: 29906.686 | W8: 9.8894374e+08 | X8: 31429 | Y8: 31465.963
Q9: J9312 | R9: Rituxan | S9: Rituximab | W9: 7.6556021e+08 | X9: 36383 | Y9: 21041.701
Q10: J9022 | R10: Tecentriq | S10: Atezolizumab | T10: 2.4075821e+08 | U10: 4896 | V10: 49174.471 | W10: 6.560749e+08 | X10: 12580 | Y10: 52152.218
Q11: J1300 | R11: Soliris | S11: Eculizumab | T11: 3.9579614e+08 | U11: 1161 | V11: 340909.68 | W11: 6.4245117e+08 | X11: 1645 | Y11: 390547.82
Q12: J2350 | R12: Ocrevus | S12: Ocrelizumab | T12: 4.8883213e+08 | U12: 9704 | V12: 50374.292 | W12: 6.0820341e+08 | X12: 12327 | Y12: 49339.126
Q13: J3380 | R13: Entyvio | S13: Vedolizumab | T13: 2.4300713e+08 | U13: 8882 | V13: 27359.506 | W13: 5.265282e+08 | X13: 15742 | Y13: 33447.351
Q14: J2505 | R14: Neulasta* | S14: Pegfilgrastim* | T14: 1370995237 | U14: 88742 | V14: 15449.226 | W14: 519022697 | X14: 57642 | Y14: 9004.2451
Q15: J1745 | R15: Remicade | S15: Infliximab | T15: 1149653207 | U15: 52085 | V15: 22072.635 | W15: 5.1262192e+08 | X15: 41903 | Y15: 12233.538
Q16: J1569 | R16: Gammagard Liquid | S16: Immun Glob G(Igg)/Gly/Iga Ov50 | T16: 3.7889106e+08 | U16: 17633 | V16: 21487.612 | W16: 5.0458623e+08 | X16: 18538 | Y16: 27219.022
Q17: J0717 | R17: Cimzia | S17: Certolizumab Pegol | T17: 3.6637106e+08 | U17: 15612 | V17: 23467.273 | W17: 5.0015267e+08 | X17: 21410 | Y17: 23360.704
Q18: J9145 | R18: Darzalex | S18: Daratumumab | T18: 6.4537545e+08 | U18: 9309 | V18: 69328.118 | W18: 4.7862818e+08 | X18: 8083 | Y18: 59214.175
Q19: J9305 | R19: Alimta | S19: Pemetrexed Disodium | T19: 4.7136965e+08 | U19: 19306 | V19: 24415.707 | W19: 4.7738148e+08 | X19: 17337 | Y19: 27535.414
Q20: 90662 | R20: Fluzone High-Dose 2015-2016* | S20: Flu Vacc TS2015-16(65yr,up)/PF* | T20: 4.6122975e+08 | U20: 9154064 | V20: 50.385245 | W20: 4.7705315e+08 | X20: 7631960 | Y20: 62.507291
Q21: J9173 | R21: Imfinzi | S21: Durvalumab | W21: 4.5354457e+08 | X21: 9073 | Y21: 49988.38
Q22: J2353 | R22: Sandostatin Lar* | S22: Octreotide Acetate,mi-Spheres* | T22: 4.1414237e+08 | U22: 9949 | V22: 41626.532 | W22: 432652274 | X22: 9465 | Y22: 45710.753
Q23: J1561 | R23: Gammaked* | S23: Immune Globul G/Gly/Iga Avg 46* | T23: 3.7045694e+08 | U23: 15991 | V23: 23166.59 | W23: 4.2359115e+08 | X23: 13442 | Y23: 31512.509
Q24: J9228 | R24: Yervoy | S24: Ipilimumab | T24: 2.6950042e+08 | U24: 4595 | V24: 58650.798 | W24: 4.080913e+08 | X24: 7687 | Y24: 53088.5
Q25: J2357 | R25: Xolair | S25: Omalizumab | T25: 3.9508335e+08 | U25: 17070 | V25: 23144.895 | W25: 4.019208e+08 | X25: 17789 | Y25: 22593.783
Q26: J1930 | R26: Somatuline Depot | S26: Lanreotide Acetate | T26: 2.0709949e+08 | U26: 4183 | V26: 49509.798 | W26: 3.9895848e+08 | X26: 6260 | Y26: 63731.386
Q27: J1602 | R27: Simponi Aria | S27: Golimumab | T27: 2.967702e+08 | U27: 16856 | V27: 17606.206 | W27: 3.7006397e+08 | X27: 26875 | Y27: 13769.822
Q28: J9035 | R28: Avastin | S28: Bevacizumab | T28: 1011988293 | U28: 224023 | V28: 4517.341 | W28: 3.6931186e+08 | X28: 154678 | Y28: 2387.6172
Q29: J0585 | R29: Botox* | S29: Onabotulinumtoxina* | T29: 3.4839152e+08 | U29: 139884 | V29: 2490.5744 | W29: 3.6644106e+08 | X29: 143146 | Y29: 2559.9113
Q30: J9041 | R30: Velcade | S30: Bortezomib | T30: 4.4337393e+08 | U30: 20262 | V30: 21882.042 | W30: 3.6279757e+08 | X30: 17267 | Y30: 21011.036
Q31: Q5107 | R31: Mvasi | S31: Bevacizumab-Awwb | W31: 336344276 | X31: 15239 | Y31: 22071.283
Q32: J9264 | R32: Abraxane | S32: Paclitaxel Protein-Bound | T32: 2.6632098e+08 | U32: 16427 | V32: 16212.393 | W32: 3.3390554e+08 | X32: 16663 | Y32: 20038.741
Q33: J1459 | R33: Privigen | S33: Immun Glob G(Igg)/Pro/Iga 0-50 | T33: 2.7436029e+08 | U33: 13725 | V33: 19989.821 | W33: 3.1173218e+08 | X33: 12064 | Y33: 25839.869
Q34: J9047 | R34: Kyprolis | S34: Carfilzomib | T34: 2.4815098e+08 | U34: 5512 | V34: 45020.135 | W34: 3.0819717e+08 | X34: 5799 | Y34: 53146.606
Q35: J3241 | R35: Tepezza | S35: Teprotumumab-Trbw | W35: 3.0269326e+08 | X35: 1163 | Y35: 260269.35
Q36: J9306 | R36: Perjeta | S36: Pertuzumab | T36: 2.6999128e+08 | U36: 7582 | V36: 35609.507 | W36: 2.9903379e+08 | X36: 7456 | Y36: 40106.464
Q37: J3262 | R37: Actemra* | S37: Tocilizumab* | T37: 2.2983152e+08 | U37: 12767 | V37: 18001.999 | W37: 2.885975e+08 | X37: 13804 | Y37: 20906.803
Q38: Q5119 | R38: Ruxience | S38: Rituximab-Pvvr | W38: 2.8850121e+08 | X38: 16546 | Y38: 17436.312
Q39: 90694 | R39: Fluad Quad 2020-2021* | S39: Flu Vacc QS2020(65up)/Mf59c/PF* | W39: 2.6925721e+08 | X39: 4239703 | Y39: 63.508508
Q40: J0896 | R40: Reblozyl | S40: Luspatercept-Aamt | W40: 2.6619136e+08 | X40: 2412 | Y40: 110361.26
...

Sheet TOP10
B1: TOP 10 MEDICATIONS WITH THE HIGHEST PMPM INCREASE (2018-2021) | Q1: YEAR | R1: BENES_FFS_CNT | T1: HCPCS_Cd | U1: Brnd_Name | V1: Tot_Spndng_2018 | W1: Tot_Spndng_2021 | X1: PMPM_2018 | Y1: PMPM_2021 | Z1: PMPM_CHANGE
B2: HCPCS_Cd | C2: Brnd_Name | D2: Tot_Spndng_2018 | E2: Tot_Spndng_2021 | F2: PMPM_2018 | G2: PMPM_2021 | H2: PMPM_CHANGE | Q2: 2018 | R2: 33503234 | T2: J9271 | U2: Keytruda | V2: 1813727267 | W2: 3966530837 | X2: =V2/(R$2*12) -> 4.5113239 | Y2: =W2/(R$3*12) -> 10.697093 | Z2: =Y2-X2 -> 6.1857694
A3: 1 | B3: J9271 | C3: Keytruda | D3: 1813727267 | E3: 3966530837 | F3: 4.5113239 | G3: 10.697093 | H3: 6.1857694 | Q3: 2021 | R3: 30900379 | T3: J9144 | U3: Darzalex Faspro | W3: 1046702030 | X3: =V3/(R$2*12) -> 0 | Y3: =W3/(R$3*12) -> 2.8227864 | Z3: =Y3-X3 -> 2.8227864
A4: 2 | B4: J9144 | C4: Darzalex Faspro | E4: 1046702030 | F4: 0 | G4: 2.8227864 | H4: 2.8227864 | T4: J0178 | U4: Eylea | V4: 2573938387 | W4: 3415890772 | X4: =V4/(R$2*12) -> 6.4022138 | Y4: =W4/(R$3*12) -> 9.2121059 | Z4: =Y4-X4 -> 2.8098922
A5: 3 | B5: J0178 | C5: Eylea | D5: 2573938387 | E5: 3415890772 | F5: 6.4022138 | G5: 9.2121059 | H5: 2.8098922 | T5: J9312 | U5: Rituxan | W5: 7.6556021e+08 | X5: =V5/(R$2*12) -> 0 | Y5: =W5/(R$3*12) -> 2.0645923 | Z5: =Y5-X5 -> 2.0645923
A6: 4 | B6: J9312 | C6: Rituxan | E6: 7.6556021e+08 | F6: 0 | G6: 2.0645923 | H6: 2.0645923 | T6: J0897 | U6: Prolia* | V6: 1416968973 | W6: 1780811015 | X6: =V6/(R$2*12) -> 3.5244582 | Y6: =W6/(R$3*12) -> 4.8025598 | Z6: =Y6-X6 -> 1.2781016
A7: 5 | B7: J0897 | C7: Prolia* | D7: 1416968973 | E7: 1780811015 | F7: 3.5244582 | G7: 4.8025598 | H7: 1.2781016 | T7: J9173 | U7: Imfinzi | W7: 4.5354457e+08 | X7: =V7/(R$2*12) -> 0 | Y7: =W7/(R$3*12) -> 1.2231365 | Z7: =Y7-X7 -> 1.2231365
A8: 6 | B8: J9173 | C8: Imfinzi | E8: 4.5354457e+08 | F8: 0 | G8: 1.2231365 | H8: 1.2231365 | T8: J9022 | U8: Tecentriq | V8: 2.4075821e+08 | W8: 6.560749e+08 | X8: =V8/(R$2*12) -> 0.59884321 | Y8: =W8/(R$3*12) -> 1.7693281 | Z8: =Y8-X8 -> 1.1704849
A9: 7 | B9: J9022 | C9: Tecentriq | D9: 2.4075821e+08 | E9: 6.560749e+08 | F9: 0.59884321 | G9: 1.7693281 | H9: 1.1704849 | T9: Q5107 | U9: Mvasi | W9: 336344276 | X9: =V9/(R$2*12) -> 0 | Y9: =W9/(R$3*12) -> 0.90706621 | Z9: =Y9-X9 -> 0.90706621
A10: 8 | B10: Q5107 | C10: Mvasi | E10: 336344276 | F10: 0 | G10: 0.90706621 | H10: 0.90706621 | T10: J3241 | U10: Tepezza | W10: 3.0269326e+08 | X10: =V10/(R$2*12) -> 0 | Y10: =W10/(R$3*12) -> 0.81631485 | Z10: =Y10-X10 -> 0.81631485
A11: 9 | B11: J3241 | C11: Tepezza | E11: 3.0269326e+08 | F11: 0 | G11: 0.81631485 | H11: 0.81631485 | T11: J3380 | U11: Entyvio | V11: 2.4300713e+08 | W11: 5.265282e+08 | X11: =V11/(R$2*12) -> 0.604437 | Y11: =W11/(R$3*12) -> 1.4199615 | Z11: =Y11-X11 -> 0.81552454
A12: 10 | B12: J3380 | C12: Entyvio | D12: 2.4300713e+08 | E12: 5.265282e+08 | F12: 0.604437 | G12: 1.4199615 | H12: 0.81552454 | T12: Q5119 | U12: Ruxience | W12: 2.8850121e+08 | X12: =V12/(R$2*12) -> 0 | Y12: =W12/(R$3*12) -> 0.77804119 | Z12: =Y12-X12 -> 0.77804119
T13: J1300 | U13: Soliris | V13: 3.9579614e+08 | W13: 6.4245117e+08 | X13: =V13/(R$2*12) -> 0.98447247 | Y13: =W13/(R$3*12) -> 1.7325871 | Z13: =Y13-X13 -> 0.7481146
T14: 90694 | U14: Fluad Quad 2020-2021* | W14: 2.6925721e+08 | X14: =V14/(R$2*12) -> 0 | Y14: =W14/(R$3*12) -> 0.72614323 | Z14: =Y14-X14 -> 0.72614323
T15: J0896 | U15: Reblozyl | W15: 2.6619136e+08 | X15: =V15/(R$2*12) -> 0 | Y15: =W15/(R$3*12) -> 0.71787512 | Z15: =Y15-X15 -> 0.71787512
T16: J0129 | U16: Orencia* | V16: 7.9928609e+08 | W16: 9.8894374e+08 | X16: =V16/(R$2*12) -> 1.9880819 | Y16: =W16/(R$3*12) -> 2.6670216 | Z16: =Y16-X16 -> 0.67893968
T17: Q5115 | U17: Truxima | W17: 2.3356605e+08 | X17: =V17/(R$2*12) -> 0 | Y17: =W17/(R$3*12) -> 0.62988993 | Z17: =Y17-X17 -> 0.62988993
T18: J1930 | U18: Somatuline Depot | V18: 2.0709949e+08 | W18: 3.9895848e+08 | X18: =V18/(R$2*12) -> 0.51512312 | Y18: =W18/(R$3*12) -> 1.0759266 | Z18: =Y18-X18 -> 0.56080348
T19: J0517 | U19: Fasenra | W19: 1.9748208e+08 | X19: =V19/(R$2*12) -> 0 | Y19: =W19/(R$3*12) -> 0.5325773 | Z19: =Y19-X19 -> 0.5325773
T20: J3111 | U20: Evenity (2 Syringes) | W20: 1.9588896e+08 | X20: =V20/(R$2*12) -> 0 | Y20: =W20/(R$3*12) -> 0.5282809 | Z20: =Y20-X20 -> 0.5282809
T21: J9119 | U21: Libtayo | W21: 1.7947004e+08 | X21: =V21/(R$2*12) -> 0 | Y21: =W21/(R$3*12) -> 0.48400173 | Z21: =Y21-X21 -> 0.48400173
T22: J7170 | U22: Hemlibra | W22: 1.7863841e+08 | X22: =V22/(R$2*12) -> 0 | Y22: =W22/(R$3*12) -> 0.48175896 | Z22: =Y22-X22 -> 0.48175896
T23: J1303 | U23: Ultomiris | W23: 1.7765413e+08 | X23: =V23/(R$2*12) -> 0 | Y23: =W23/(R$3*12) -> 0.47910451 | Z23: =Y23-X23 -> 0.47910451
T24: Q5118 | U24: Zirabev | W24: 1.7247189e+08 | X24: =V24/(R$2*12) -> 0 | Y24: =W24/(R$3*12) -> 0.46512883 | Z24: =Y24-X24 -> 0.46512883
T25: J0717 | U25: Cimzia | V25: 3.6637106e+08 | W25: 5.0015267e+08 | X25: =V25/(R$2*12) -> 0.91128283 | Y25: =W25/(R$3*12) -> 1.348831 | Z25: =Y25-X25 -> 0.43754818
T26: Q5111 | U26: Udenyca | W26: 1.6004288e+08 | X26: =V26/(R$2*12) -> 0 | Y26: =W26/(R$3*12) -> 0.43160981 | Z26: =Y26-X26 -> 0.43160981
T27: J9228 | U27: Yervoy | V27: 2.6950042e+08 | W27: 4.080913e+08 | X27: =V27/(R$2*12) -> 0.67033433 | Y27: =W27/(R$3*12) -> 1.1005564 | Z27: =Y27-X27 -> 0.43022202
T28: Q5117 | U28: Kanjinti | W28: 1.5930983e+08 | X28: =V28/(R$2*12) -> 0 | Y28: =W28/(R$3*12) -> 0.42963289 | Z28: =Y28-X28 -> 0.42963289
T29: J2350 | U29: Ocrevus | V29: 4.8883213e+08 | W29: 6.0820341e+08 | X29: =V29/(R$2*12) -> 1.2158829 | Y29: =W29/(R$3*12) -> 1.6402264 | Z29: =Y29-X29 -> 0.42434345
T30: J1569 | U30: Gammagard Liquid | V30: 3.7889106e+08 | W30: 5.0458623e+08 | X30: =V30/(R$2*12) -> 0.9424241 | Y30: =W30/(R$3*12) -> 1.3607876 | Z30: =Y30-X30 -> 0.4183635
T31: J9177 | U31: Padcev | W31: 1.5435558e+08 | X31: =V31/(R$2*12) -> 0 | Y31: =W31/(R$3*12) -> 0.41627207 | Z31: =Y31-X31 -> 0.41627207
T32: J3245 | U32: Ilumya | W32: 1.4458376e+08 | X32: =V32/(R$2*12) -> 0 | Y32: =W32/(R$3*12) -> 0.38991905 | Z32: =Y32-X32 -> 0.38991905
T33: J7677 | U33: Yupelri | W33: 1.3816455e+08 | X33: =V33/(R$2*12) -> 0 | Y33: =W33/(R$3*12) -> 0.3726075 | Z33: =Y33-X33 -> 0.3726075
T34: J3357 | U34: Stelara (J3357) | V34: 1.5322342e+08 | W34: 2.5425381e+08 | X34: =V34/(R$2*12) -> 0.38111599 | Y34: =W34/(R$3*12) -> 0.68568148 | Z34: =Y34-X34 -> 0.30456549
T35: J9358 | U35: Enhertu | W35: 1.0911897e+08 | X35: =V35/(R$2*12) -> 0 | Y35: =W35/(R$3*12) -> 0.29427626 | Z35: =Y35-X35 -> 0.29427626
T36: J2182 | U36: Nucala | V36: 1.1848456e+08 | W36: 2.1051871e+08 | X36: =V36/(R$2*12) -> 0.29470926 | Y36: =W36/(R$3*12) -> 0.56773497 | Z36: =Y36-X36 -> 0.27302571
T37: J1602 | U37: Simponi Aria | V37: 2.967702e+08 | W37: 3.7006397e+08 | X37: =V37/(R$2*12) -> 0.73816307 | Y37: =W37/(R$3*12) -> 0.99800279 | Z37: =Y37-X37 -> 0.25983972
T38: J9317 | U38: Trodelvy | W38: 96029681 | X38: =V38/(R$2*12) -> 0 | Y38: =W38/(R$3*12) -> 0.25897654 | Z38: =Y38-X38 -> 0.25897654
T39: J1559 | U39: Hizentra | V39: 1.3901393e+08 | W39: 2.2255265e+08 | X39: =V39/(R$2*12) -> 0.34577243 | Y39: =W39/(R$3*12) -> 0.60018857 | Z39: =Y39-X39 -> 0.25441615
T40: J2507 | U40: Krystexxa | V40: 72284678 | W40: 1.6019775e+08 | X40: =V40/(R$2*12) -> 0.17979528 | Y40: =W40/(R$3*12) -> 0.43202746 | Z40: =Y40-X40 -> 0.25223219
...

Sheet ENTYVIO
A1: ENTYVIO ANALYSIS
B2: 2018 | C2: 2021
A3: Total Spend | B3: =E24 -> 2.4300713e+08 | C3: =M24 -> 5.265282e+08
A4: Patients | B4: =H24 -> 8882 | C4: =P24 -> 15742
A5: Price per Patient | B5: =B3/B4 -> 27359.506 | C5: =C3/C4 -> 33447.351
A7: Total Spending Change | B7: Volume Change | C7: Unit Price Change
A8: =C3-B3 -> 2.8352107e+08 | B8: =(C4-B4)*B5 -> 1.8768621e+08 | C8: =(C5-B5)*C4 -> 95834856
A9: % of Change | B9: =B8/A8 -> 0.6619833 | C9: =C8/A8 -> 0.3380167
A23: HCPCS_Cd | B23: HCPCS_Desc | C23: Brnd_Name | D23: Gnrc_Name | E23: Tot_Spndng_2018 | F23: Tot_Dsg_Unts_2018 | G23: Tot_Clms_2018 | H23: Tot_Benes_2018 | I23: Avg_Spndng_Per_Dsg_Unt_2018 | J23: Avg_Spndng_Per_Clm_2018 | K23: Avg_Spndng_Per_Bene_2018 | L23: Outlier_Flag_2018 | M23: Tot_Spndng_2021 | N23: Tot_Dsg_Unts_2021 | O23: Tot_Clms_2021 | P23: Tot_Benes_2021 | Q23: Avg_Spndng_Per_Dsg_Unt_2021 | R23: Avg_Spndng_Per_Clm_2021 | S23: Avg_Spndng_Per_Bene_2021 | T23: Outlier_Flag_2021 | U23: Avg_DY21_ASP_Price | V23: Chg_Avg_Spndng_Per_Dsg_Unt_20_21 | W23: CAGR_Avg_Spnd_Per_Dsg_Unt_17_21
A24: J3380 | B24: Injection, vedolizumab | C24: Entyvio | D24: Vedolizumab | E24: 2.4300713e+08 | F24: 14114303 | G24: 46859 | H24: 8882 | I24: 17.217083 | J24: 5185.9223 | K24: 27359.506 | L24: 0 | M24: 5.265282e+08 | N24: 27759023 | O24: 92268 | P24: 15742 | Q24: 18.967822 | R24: 5706.5093 | S24: 33447.351 | T24: 0 | U24: 20.827 | V24: 0.028896152 | W24: 0.016592144

Sheet BIOSIM_ANALYSIS
A1: 2021 BIOSIMILAR GROSS IMPACT ANALYSIS
A2: HCPCS_Cd | B2: Brnd_Name | C2: Tot_Spndng_2021 | D2: Tot_Benes_2021 | E2: Avg_Spndng_Per_Bene_2021 | F2: REF_PRODUCT_FLAG | G2: REF_PRODUCT_CLASS | H2: PREFERRED_DRUG | I2: BENCHMARK_REF_PRICE | J2: HYPOTHETICAL_SPEND_2021 | K2: SAVINGS_2021
A3: J9355 | B3: Herceptin | C3: 2.2370977e+08 | D3: 6944 | E3: 32216.269 | F3: Y | G3: HERCEPTIN | H3: N | I3: =E$3 -> 32216.269 | J3: =I3*D3 -> 2.2370977e+08 | K3: =IF(F3="N", J3 - C3, 0) -> 0
A4: Q5117 | B4: Kanjinti | C4: 1.5930983e+08 | D4: 7550 | E4: 21100.64 | F4: N | G4: HERCEPTIN | H4: Y | I4: =E$3 -> 32216.269 | J4: =I4*D4 -> 2.4323283e+08 | K4: =IF(F4="N", J4 - C4, 0) -> 83923001
A5: Q5116 | B5: Trazimera | C5: 59996202 | D5: 2993 | E5: 20045.507 | F5: N | G5: HERCEPTIN | H5: Y | I5: =E$3 -> 32216.269 | J5: =I5*D5 -> 96423293 | K5: =IF(F5="N", J5 - C5, 0) -> 36427091
A6: Q5114 | B6: Ogivri | C6: 46807920 | D6: 2257 | E6: 20738.999 | F6: N | G6: HERCEPTIN | H6: Y | I6: =E$3 -> 32216.269 | J6: =I6*D6 -> 72712119 | K6: =IF(F6="N", J6 - C6, 0) -> 25904199
A7: J9356 | B7: Herceptin Hylecta | C7: 19235278 | D7: 597 | E7: 32219.896 | F7: Y | G7: HERCEPTIN | H7: N | I7: =E$3 -> 32216.269 | J7: =I7*D7 -> 19233113 | K7: =IF(F7="N", J7 - C7, 0) -> 0
A8: Q5112 | B8: Ontruzant | C8: 11340522 | D8: 531 | E8: 21356.916 | F8: N | G8: HERCEPTIN | H8: Y | I8: =E$3 -> 32216.269 | J8: =I8*D8 -> 17106839 | K8: =IF(F8="N", J8 - C8, 0) -> 5766316.4
A9: Q5113 | B9: Herzuma | C9: 7706641.7 | D9: 329 | E9: 23424.443 | F9: N | G9: HERCEPTIN | H9: Y | I9: =E$3 -> 32216.269 | J9: =I9*D9 -> 10599152 | K9: =IF(F9="N", J9 - C9, 0) -> 2892510.8
A10: J2505 | B10: Neulasta* | C10: 519022697 | D10: 57642 | E10: 9004.2451 | F10: Y | G10: NEULASTA | H10: N | I10: =E$10 -> 9004.2451 | J10: =I10*D10 -> 5.190227e+08 | K10: =IF(F10="N", J10 - C10, 0) -> 0
A11: Q5111 | B11: Udenyca | C11: 1.6004288e+08 | D11: 15627 | E11: 10241.433 | F11: N | G11: NEULASTA | H11: Y | I11: =E$10 -> 9004.2451 | J11: =I11*D11 -> 1.4070934e+08 | K11: =IF(F11="N", J11 - C11, 0) -> -19333541
A12: Q5120 | B12: Ziextenzo | C12: 85195358 | D12: 7991 | E12: 10661.414 | F12: N | G12: NEULASTA | H12: Y | I12: =E$10 -> 9004.2451 | J12: =I12*D12 -> 71952923 | K12: =IF(F12="N", J12 - C12, 0) -> -13242435
A13: Q5108 | B13: Fulphila | C13: 75403321 | D13: 8069 | E13: 9344.8161 | F13: N | G13: NEULASTA | H13: Y | I13: =E$10 -> 9004.2451 | J13: =I13*D13 -> 72655254 | K13: =IF(F13="N", J13 - C13, 0) -> -2748067.1
A14: Q5122 | B14: Nyvepria | C14: 26671091 | D14: 2086 | E14: 12785.758 | F14: N | G14: NEULASTA | H14: Y | I14: =E$10 -> 9004.2451 | J14: =I14*D14 -> 18782855 | K14: =IF(F14="N", J14 - C14, 0) -> -7888235.3
A15: Q5101 | B15: Zarxio | C15: 18684232 | D15: 18746 | E15: 996.70501 | F15: N | G15: NEUPOGEN | H15: Y | I15: =E$16 -> 2413.9227 | J15: =I15*D15 -> 45251395 | K15: =IF(F15="N", J15 - C15, 0) -> 26567163
A16: J1442 | B16: Neupogen | C16: 16004308 | D16: 6630 | E16: 2413.9227 | F16: Y | G16: NEUPOGEN | H16: N | I16: =E$16 -> 2413.9227 | J16: =I16*D16 -> 16004308 | K16: =IF(F16="N", J16 - C16, 0) -> 0
A17: Q5110 | B17: Nivestym | C17: 4915196 | D17: 3741 | E17: 1313.8722 | F17: N | G17: NEUPOGEN | H17: Y | I17: =E$16 -> 2413.9227 | J17: =I17*D17 -> 9030484.8 | K17: =IF(F17="N", J17 - C17, 0) -> 4115288.8
A18: Q5106 | B18: Retacrit (Q5106) | C18: 87251750 | D18: 37266 | E18: 2341.3232 | F18: N | G18: PROCRIT | H18: Y | I18: =E$19 -> 2255.699 | J18: =I18*D18 -> 84060878 | K18: =IF(F18="N", J18 - C18, 0) -> -3190872.2
A19: J0885 | B19: Epogen (J0885)* | C19: 58454183 | D19: 25914 | E19: 2255.699 | F19: Y | G19: PROCRIT | H19: N | I19: =E$19 -> 2255.699 | J19: =I19*D19 -> 58454183 | K19: =IF(F19="N", J19 - C19, 0) -> 0
A20: Q5105 | B20: Retacrit (Q5105) | C20: 1127418.2 | D20: 4543 | E20: 248.166 | F20: N | G20: PROCRIT | H20: Y | I20: =E$19 -> 2255.699 | J20: =I20*D20 -> 10247640 | K20: =IF(F20="N", J20 - C20, 0) -> 9120222.3
A21: Q4081 | B21: Epogen (Q4081)* | C21: 14004.02 | D21: 21 | E21: 666.8581 | F21: Y | G21: PROCRIT | H21: N | I21: =E$19 -> 2255.699 | J21: =I21*D21 -> 47369.678 | K21: =IF(F21="N", J21 - C21, 0) -> 0
A22: J1745 | B22: Remicade | C22: 5.1262192e+08 | D22: 41903 | E22: 12233.538 | F22: Y | G22: REMICADE | H22: N | I22: =E$22 -> 12233.538 | J22: =I22*D22 -> 5.1262192e+08 | K22: =IF(F22="N", J22 - C22, 0) -> 0
A23: Q5103 | B23: Inflectra | C23: 71993955 | D23: 7268 | E23: 9905.6074 | F23: N | G23: REMICADE | H23: Y | I23: =E$22 -> 12233.538 | J23: =I23*D23 -> 88913351 | K23: =IF(F23="N", J23 - C23, 0) -> 16919396
A24: Q5104 | B24: Renflexis | C24: 51022400 | D24: 5358 | E24: 9522.6576 | F24: N | G24: REMICADE | H24: Y | I24: =E$22 -> 12233.538 | J24: =I24*D24 -> 65547294 | K24: =IF(F24="N", J24 - C24, 0) -> 14524895
A25: Q5121 | B25: Avsola | C25: 9946500.2 | D25: 1175 | E25: 8465.1066 | F25: N | G25: REMICADE | H25: Y | I25: =E$22 -> 12233.538 | J25: =I25*D25 -> 14374407 | K25: =IF(F25="N", J25 - C25, 0) -> 4427906.4
A26: J9312 | B26: Rituxan | C26: 7.6556021e+08 | D26: 36383 | E26: 21041.701 | F26: Y | G26: RITUXAN | H26: N | I26: =E$26 -> 21041.701 | J26: =I26*D26 -> 7.6556021e+08 | K26: =IF(F26="N", J26 - C26, 0) -> 0
A27: Q5119 | B27: Ruxience | C27: 2.8850121e+08 | D27: 16546 | E27: 17436.312 | F27: N | G27: RITUXAN | H27: Y | I27: =E$26 -> 21041.701 | J27: =I27*D27 -> 3.4815598e+08 | K27: =IF(F27="N", J27 - C27, 0) -> 59654773
A28: Q5115 | B28: Truxima | C28: 2.3356605e+08 | D28: 13932 | E28: 16764.718 | F28: N | G28: RITUXAN | H28: Y | I28: =E$26 -> 21041.701 | J28: =I28*D28 -> 2.9315298e+08 | K28: =IF(F28="N", J28 - C28, 0) -> 59586927
A29: J9311 | B29: Rituxan Hycela | C29: 68338781 | D29: 3580 | E29: 19089.045 | F29: Y | G29: RITUXAN | H29: N | I29: =E$26 -> 21041.701 | J29: =I29*D29 -> 75329289 | K29: =IF(F29="N", J29 - C29, 0) -> 0
A30: Q5123 | B30: Riabni | C30: 11960083 | D30: 782 | E30: 15294.224 | F30: N | G30: RITUXAN | H30: Y | I30: =E$26 -> 21041.701 | J30: =I30*D30 -> 16454610 | K30: =IF(F30="N", J30 - C30, 0) -> 4494527.1
J31: Total Savings | K31: =SUM(K3:K30) -> 3.0792107e+08

Sheet BIOSIM_2021
A1: HCPCS_Cd | B1: Brnd_Name | C1: Tot_Spndng_2021 | D1: Tot_Benes_2021 | E1: Avg_Spndng_Per_Bene_2021 | F1: REF_PRODUCT_FLAG | G1: REF_PRODUCT_CLASS | H1: PREFERRED_DRUG
A2: J9271 | B2: Keytruda | C2: 3966530837 | D2: 62830 | E2: 63131.161 | F2: =VLOOKUP(A2, BIOSIM_REF!$A:$E, 3, FALSE) -> #N/A | G2: =VLOOKUP(A2, BIOSIM_REF!$A:$E, 4, FALSE) -> #N/A | H2: =VLOOKUP(A2, BIOSIM_REF!$A:$E, 5, FALSE) -> #N/A
A3: J0178 | B3: Eylea | C3: 3415890772 | D3: 309699 | E3: 11029.712 | F3: =VLOOKUP(A3, BIOSIM_REF!$A:$E, 3, FALSE) -> #N/A | G3: =VLOOKUP(A3, BIOSIM_REF!$A:$E, 4, FALSE) -> #N/A | H3: =VLOOKUP(A3, BIOSIM_REF!$A:$E, 5, FALSE) -> #N/A
A4: J0897 | B4: Prolia* | C4: 1780811015 | D4: 629724 | E4: 2827.923 | F4: =VLOOKUP(A4, BIOSIM_REF!$A:$E, 3, FALSE) -> #N/A | G4: =VLOOKUP(A4, BIOSIM_REF!$A:$E, 4, FALSE) -> #N/A | H4: =VLOOKUP(A4, BIOSIM_REF!$A:$E, 5, FALSE) -> #N/A
A5: J9299 | B5: Opdivo | C5: 1573611853 | D5: 25426 | E5: 61889.871 | F5: =VLOOKUP(A5, BIOSIM_REF!$A:$E, 3, FALSE) -> #N/A | G5: =VLOOKUP(A5, BIOSIM_REF!$A:$E, 4, FALSE) -> #N/A | H5: =VLOOKUP(A5, BIOSIM_REF!$A:$E, 5, FALSE) -> #N/A
A6: J9144 | B6: Darzalex Faspro | C6: 1046702030 | D6: 12490 | E6: 83803.205 | F6: =VLOOKUP(A6, BIOSIM_REF!$A:$E, 3, FALSE) -> #N/A | G6: =VLOOKUP(A6, BIOSIM_REF!$A:$E, 4, FALSE) -> #N/A | H6: =VLOOKUP(A6, BIOSIM_REF!$A:$E, 5, FALSE) -> #N/A
A7: J2778 | B7: Lucentis | C7: 1044929993 | D7: 114432 | E7: 9131.4492 | F7: =VLOOKUP(A7, BIOSIM_REF!$A:$E, 3, FALSE) -> #N/A | G7: =VLOOKUP(A7, BIOSIM_REF!$A:$E, 4, FALSE) -> #N/A | H7: =VLOOKUP(A7, BIOSIM_REF!$A:$E, 5, FALSE) -> #N/A
A8: J0129 | B8: Orencia* | C8: 9.8894374e+08 | D8: 31429 | E8: 31465.963 | F8: =VLOOKUP(A8, BIOSIM_REF!$A:$E, 3, FALSE) -> #N/A | G8: =VLOOKUP(A8, BIOSIM_REF!$A:$E, 4, FALSE) -> #N/A | H8: =VLOOKUP(A8, BIOSIM_REF!$A:$E, 5, FALSE) -> #N/A
A9: J9355 | B9: Herceptin | C9: 2.2370977e+08 | D9: 6944 | E9: 32216.269 | F9: =VLOOKUP(A9, BIOSIM_REF!$A:$E, 3, FALSE) -> Y | G9: =VLOOKUP(A9, BIOSIM_REF!$A:$E, 4, FALSE) -> HERCEPTIN | H9: =VLOOKUP(A9, BIOSIM_REF!$A:$E, 5, FALSE) -> N
A10: J9022 | B10: Tecentriq | C10: 6.560749e+08 | D10: 12580 | E10: 52152.218 | F10: =VLOOKUP(A10, BIOSIM_REF!$A:$E, 3, FALSE) -> #N/A | G10: =VLOOKUP(A10, BIOSIM_REF!$A:$E, 4, FALSE) -> #N/A | H10: =VLOOKUP(A10, BIOSIM_REF!$A:$E, 5, FALSE) -> #N/A
A11: J1300 | B11: Soliris | C11: 6.4245117e+08 | D11: 1645 | E11: 390547.82 | F11: =VLOOKUP(A11, BIOSIM_REF!$A:$E, 3, FALSE) -> #N/A | G11: =VLOOKUP(A11, BIOSIM_REF!$A:$E, 4, FALSE) -> #N/A | H11: =VLOOKUP(A11, BIOSIM_REF!$A:$E, 5, FALSE) -> #N/A
A12: J2350 | B12: Ocrevus | C12: 6.0820341e+08 | D12: 12327 | E12: 49339.126 | F12: =VLOOKUP(A12, BIOSIM_REF!$A:$E, 3, FALSE) -> #N/A | G12: =VLOOKUP(A12, BIOSIM_REF!$A:$E, 4, FALSE) -> #N/A | H12: =VLOOKUP(A12, BIOSIM_REF!$A:$E, 5, FALSE) -> #N/A
A13: J3380 | B13: Entyvio | C13: 5.265282e+08 | D13: 15742 | E13: 33447.351 | F13: =VLOOKUP(A13, BIOSIM_REF!$A:$E, 3, FALSE) -> #N/A | G13: =VLOOKUP(A13, BIOSIM_REF!$A:$E, 4, FALSE) -> #N/A | H13: =VLOOKUP(A13, BIOSIM_REF!$A:$E, 5, FALSE) -> #N/A
... A19: J9305 | B19: Alimta | C19: 4.7738148e+08 | D19: 17337 | E19: 27535.414 | F19: =VLOOKUP(A19, BIOSIM_REF!$A:$E, 3, FALSE) -> #N/A | G19: =VLOOKUP(A19, BIOSIM_REF!$A:$E, 4, FALSE) -> #N/A | H19: =VLOOKUP(A19, BIOSIM_REF!$A:$E, 5, FALSE) -> #N/A
A20: 90662 | B20: Fluzone High-Dose 2015-2016* | C20: 4.7705315e+08 | D20: 7631960 | E20: 62.507291 | F20: =VLOOKUP(A20, BIOSIM_REF!$A:$E, 3, FALSE) -> #N/A | G20: =VLOOKUP(A20, BIOSIM_REF!$A:$E, 4, FALSE) -> #N/A | H20: =VLOOKUP(A20, BIOSIM_REF!$A:$E, 5, FALSE) -> #N/A
A21: J9173 | B21: Imfinzi | C21: 4.5354457e+08 | D21: 9073 | E21: 49988.38 | F21: =VLOOKUP(A21, BIOSIM_REF!$A:$E, 3, FALSE) -> #N/A | G21: =VLOOKUP(A21, BIOSIM_REF!$A:$E, 4, FALSE) -> #N/A | H21: =VLOOKUP(A21, BIOSIM_REF!$A:$E, 5, FALSE) -> #N/A
A22: J2353 | B22: Sandostatin Lar* | C22: 432652274 | D22: 9465 | E22: 45710.753 | F22: =VLOOKUP(A22, BIOSIM_REF!$A:$E, 3, FALSE) -> #N/A | G22: =VLOOKUP(A22, BIOSIM_REF!$A:$E, 4, FALSE) -> #N/A | H22: =VLOOKUP(A22, BIOSIM_REF!$A:$E, 5, FALSE) -> #N/A
A23: J1561 | B23: Gammaked* | C23: 4.2359115e+08 | D23: 13442 | E23: 31512.509 | F23: =VLOOKUP(A23, BIOSIM_REF!$A:$E, 3, FALSE) -> #N/A | G23: =VLOOKUP(A23, BIOSIM_REF!$A:$E, 4, FALSE) -> #N/A | H23: =VLOOKUP(A23, BIOSIM_REF!$A:$E, 5, FALSE) -> #N/A
A24: J9228 | B24: Yervoy | C24: 4.080913e+08 | D24: 7687 | E24: 53088.5 | F24: =VLOOKUP(A24, BIOSIM_REF!$A:$E, 3, FALSE) -> #N/A | G24: =VLOOKUP(A24, BIOSIM_REF!$A:$E, 4, FALSE) -> #N/A | H24: =VLOOKUP(A24, BIOSIM_REF!$A:$E, 5, FALSE) -> #N/A
A25: J2357 | B25: Xolair | C25: 4.019208e+08 | D25: 17789 | E25: 22593.783 | F25: =VLOOKUP(A25, BIOSIM_REF!$A:$E, 3, FALSE) -> #N/A | G25: =VLOOKUP(A25, BIOSIM_REF!$A:$E, 4, FALSE) -> #N/A | H25: =VLOOKUP(A25, BIOSIM_REF!$A:$E, 5, FALSE) -> #N/A
A26: J1930 | B26: Somatuline Depot | C26: 3.9895848e+08 | D26: 6260 | E26: 63731.386 | F26: =VLOOKUP(A26, BIOSIM_REF!$A:$E, 3, FALSE) -> #N/A | G26: =VLOOKUP(A26, BIOSIM_REF!$A:$E, 4, FALSE) -> #N/A | H26: =VLOOKUP(A26, BIOSIM_REF!$A:$E, 5, FALSE) -> #N/A
A27: J1602 | B27: Simponi Aria | C27: 3.7006397e+08 | D27: 26875 | E27: 13769.822 | F27: =VLOOKUP(A27, BIOSIM_REF!$A:$E, 3, FALSE) -> #N/A | G27: =VLOOKUP(A27, BIOSIM_REF!$A:$E, 4, FALSE) -> #N/A | H27: =VLOOKUP(A27, BIOSIM_REF!$A:$E, 5, FALSE) -> #N/A
A28: J9035 | B28: Avastin | C28: 3.6931186e+08 | D28: 154678 | E28: 2387.6172 | F28: =VLOOKUP(A28, BIOSIM_REF!$A:$E, 3, FALSE) -> #N/A | G28: =VLOOKUP(A28, BIOSIM_REF!$A:$E, 4, FALSE) -> #N/A | H28: =VLOOKUP(A28, BIOSIM_REF!$A:$E, 5, FALSE) -> #N/A
A29: J0585 | B29: Botox* | C29: 3.6644106e+08 | D29: 143146 | E29: 2559.9113 | F29: =VLOOKUP(A29, BIOSIM_REF!$A:$E, 3, FALSE) -> #N/A | G29: =VLOOKUP(A29, BIOSIM_REF!$A:$E, 4, FALSE) -> #N/A | H29: =VLOOKUP(A29, BIOSIM_REF!$A:$E, 5, FALSE) -> #N/A
A30: J9041 | B30: Velcade | C30: 3.6279757e+08 | D30: 17267 | E30: 21011.036 | F30: =VLOOKUP(A30, BIOSIM_REF!$A:$E, 3, FALSE) -> #N/A | G30: =VLOOKUP(A30, BIOSIM_REF!$A:$E, 4, FALSE) -> #N/A | H30: =VLOOKUP(A30, BIOSIM_REF!$A:$E, 5, FALSE) -> #N/A
A31: Q5107 | B31: Mvasi | C31: 336344276 | D31: 15239 | E31: 22071.283 | F31: =VLOOKUP(A31, BIOSIM_REF!$A:$E, 3, FALSE) -> #N/A | G31: =VLOOKUP(A31, BIOSIM_REF!$A:$E, 4, FALSE) -> #N/A | H31: =VLOOKUP(A31, BIOSIM_REF!$A:$E, 5, FALSE) -> #N/A
A32: J9264 | B32: Abraxane | C32: 3.3390554e+08 | D32: 16663 | E32: 20038.741 | F32: =VLOOKUP(A32, BIOSIM_REF!$A:$E, 3, FALSE) -> #N/A | G32: =VLOOKUP(A32, BIOSIM_REF!$A:$E, 4, FALSE) -> #N/A | H32: =VLOOKUP(A32, BIOSIM_REF!$A:$E, 5, FALSE) -> #N/A
... A38: Q5114 | B38: Ogivri | C38: 46807920 | D38: 2257 | E38: 20738.999 | F38: =VLOOKUP(A38, BIOSIM_REF!$A:$E, 3, FALSE) -> N | G38: =VLOOKUP(A38, BIOSIM_REF!$A:$E, 4, FALSE) -> HERCEPTIN | H38: =VLOOKUP(A38, BIOSIM_REF!$A:$E, 5, FALSE) -> Y
A39: 90694 | B39: Fluad Quad 2020-2021* | C39: 2.6925721e+08 | D39: 4239703 | E39: 63.508508 | F39: =VLOOKUP(A39, BIOSIM_REF!$A:$E, 3, FALSE) -> #N/A | G39: =VLOOKUP(A39, BIOSIM_REF!$A:$E, 4, FALSE) -> #N/A | H39: =VLOOKUP(A39, BIOSIM_REF!$A:$E, 5, FALSE) -> #N/A
A40: J0896 | B40: Reblozyl | C40: 2.6619136e+08 | D40: 2412 | E40: 110361.26 | F40: =VLOOKUP(A40, BIOSIM_REF!$A:$E, 3, FALSE) -> #N/A | G40: =VLOOKUP(A40, BIOSIM_REF!$A:$E, 4, FALSE) -> #N/A | H40: =VLOOKUP(A40, BIOSIM_REF!$A:$E, 5, FALSE) -> #N/A
A41: J3357 | B41: Stelara (J3357) | C41: 2.5425381e+08 | D41: 5471 | E41: 46473.005 | F41: =VLOOKUP(A41, BIOSIM_REF!$A:$E, 3, FALSE) -> #N/A | G41: =VLOOKUP(A41, BIOSIM_REF!$A:$E, 4, FALSE) -> #N/A | H41: =VLOOKUP(A41, BIOSIM_REF!$A:$E, 5, FALSE) -> #N/A
A42: J7686 | B42: Tyvaso* | C42: 2.5387501e+08 | D42: 1713 | E42: 148204.91 | F42: =VLOOKUP(A42, BIOSIM_REF!$A:$E, 3, FALSE) -> #N/A | G42: =VLOOKUP(A42, BIOSIM_REF!$A:$E, 4, FALSE) -> #N/A | H42: =VLOOKUP(A42, BIOSIM_REF!$A:$E, 5, FALSE) -> #N/A
A43: J2796 | B43: NPlate | C43: 248357392 | D43: 4961 | E43: 50061.962 | F43: =VLOOKUP(A43, BIOSIM_REF!$A:$E, 3, FALSE) -> #N/A | G43: =VLOOKUP(A43, BIOSIM_REF!$A:$E, 4, FALSE) -> #N/A | H43: =VLOOKUP(A43, BIOSIM_REF!$A:$E, 5, FALSE) -> #N/A
A44: J1568 | B44: Octagam | C44: 2.4338734e+08 | D44: 9609 | E44: 25329.101 | F44: =VLOOKUP(A44, BIOSIM_REF!$A:$E, 3, FALSE) -> #N/A | G44: =VLOOKUP(A44, BIOSIM_REF!$A:$E, 4, FALSE) -> #N/A | H44: =VLOOKUP(A44, BIOSIM_REF!$A:$E, 5, FALSE) -> #N/A
A45: J9356 | B45: Herceptin Hylecta | C45: 19235278 | D45: 597 | E45: 32219.896 | F45: =VLOOKUP(A45, BIOSIM_REF!$A:$E, 3, FALSE) -> Y | G45: =VLOOKUP(A45, BIOSIM_REF!$A:$E, 4, FALSE) -> HERCEPTIN | H45: =VLOOKUP(A45, BIOSIM_REF!$A:$E, 5, FALSE) -> N
A46: J9217 | B46: Eligard* | C46: 224127403 | D46: 155959 | E46: 1437.0918 | F46: =VLOOKUP(A46, BIOSIM_REF!$A:$E, 3, FALSE) -> #N/A | G46: =VLOOKUP(A46, BIOSIM_REF!$A:$E, 4, FALSE) -> #N/A | H46: =VLOOKUP(A46, BIOSIM_REF!$A:$E, 5, FALSE) -> #N/A
A47: Q5112 | B47: Ontruzant | C47: 11340522 | D47: 531 | E47: 21356.916 | F47: =VLOOKUP(A47, BIOSIM_REF!$A:$E, 3, FALSE) -> N | G47: =VLOOKUP(A47, BIOSIM_REF!$A:$E, 4, FALSE) -> HERCEPTIN | H47: =VLOOKUP(A47, BIOSIM_REF!$A:$E, 5, FALSE) -> Y
A48: J1559 | B48: Hizentra | C48: 2.2255265e+08 | D48: 4551 | E48: 48901.923 | F48: =VLOOKUP(A48, BIOSIM_REF!$A:$E, 3, FALSE) -> #N/A | G48: =VLOOKUP(A48, BIOSIM_REF!$A:$E, 4, FALSE) -> #N/A | H48: =VLOOKUP(A48, BIOSIM_REF!$A:$E, 5, FALSE) -> #N/A
A49: J2182 | B49: Nucala | C49: 2.1051871e+08 | D49: 8141 | E49: 25859.072 | F49: =VLOOKUP(A49, BIOSIM_REF!$A:$E, 3, FALSE) -> #N/A | G49: =VLOOKUP(A49, BIOSIM_REF!$A:$E, 4, FALSE) -> #N/A | H49: =VLOOKUP(A49, BIOSIM_REF!$A:$E, 5, FALSE) -> #N/A
A50: J2323 | B50: Tysabri | C50: 2.0801722e+08 | D50: 4208 | E50: 49433.749 | F50: =VLOOKUP(A50, BIOSIM_REF!$A:$E, 3, FALSE) -> #N/A | G50: =VLOOKUP(A50, BIOSIM_REF!$A:$E, 4, FALSE) -> #N/A | H50: =VLOOKUP(A50, BIOSIM_REF!$A:$E, 5, FALSE) -> #N/A
...

Sheet BIOSIM_REF
A1: PROC_CD | B1: BRAND_NAME | C1: REF_PRODUCT_FLG | D1: REF_PRODUCT_CLASS | E1: PREFERRED_DRUG
A2: J9356 | B2: HERCEPTIN HYLECTA | C2: Y | D2: HERCEPTIN | E2: N
A3: J9355 | B3: HERCEPTIN | C3: Y | D3: HERCEPTIN | E3: N
A4: Q5113 | B4: HERZUMA | C4: N | D4: HERCEPTIN | E4: Y
A5: Q5114 | B5: OGIVRI | C5: N | D5: HERCEPTIN | E5: Y
A6: Q5112 | B6: ONTRUZANT | C6: N | D6: HERCEPTIN | E6: Y
A7: Q5117 | B7: KANJINTI | C7: N | D7: HERCEPTIN | E7: Y
A8: Q5116 | B8: TRAZIMERA | C8: N | D8: HERCEPTIN | E8: Y
A9: J2505 | B9: NEULASTA | C9: Y | D9: NEULASTA | E9: N
A10: J2506 | B10: NEULASTA | C10: Y | D10: NEULASTA | E10: N
A11: Q5108 | B11: FULPHILA | C11: N | D11: NEULASTA | E11: Y
A12: Q5122 | B12: NYVEPRIA | C12: N | D12: NEULASTA | E12: Y
... A36: Q5123 | B36: RIABNI | C36: N | D36: RITUXAN | E36: Y
